Workbook

Sheet Bhf
A1: Bundesland | B1: BM | C1: Bahnhofnummer | D1: Station | E1: Betriebsstelle | F1: Kategorie | G1: Strasse | H1: PLZ | I1: Port | J1: Aufgabenträger | K1: Abkürzung | L1: Fernverkehr | M1: Nahverkehr | N1: Lat | O1: Lon
D2: Altheim (Hess) | N2: 49.92272 | O2: 8.89136
D3: Babenhausen (Hess) | N3: 49.95808 | O3: 8.95714
D4: Babenhausen Langstadt | N4: 49.92226 | O4: 8.94588
D5: Bad König | N5: 49.73884 | O5: 9.00186
D6: Bad König-Zell | N6: 49.72047 | O6: 8.99413
D7: Beerfelden-Hetzbach | N7: 49.5948 | O7: 8.9924
D8: Bensheim | N8: 49.68122 | O8: 8.61708
D9: Bensheim-Auerbach | N9: 49.70241 | O9: 8.61321
D10: Biblis | N10: 49.68909 | O10: 8.45137
D11: Bickenbach (Bergstr) | N11: 49.75949 | O11: 8.60366
D12: Biebesheim | N12: 49.78101 | O12: 8.47373
D13: Bobstadt | N13: 49.66327 | O13: 8.45123
... D692: Lebach-Jabach | N692: 49.40649 | O692: 6.89239
D693: Limbach (b Homburg | N693: 7.27846 | O693: ja
D694: Luisenthal (Saar) | N694: 49.24921 | O694: 6.90429
D695: Merchweiler | N695: 49.35445 | O695: 7.06359
D696: Merzig (Saar) | N696: 49.35643 | O696: 6.71547
D697: Merzig Stadtmitte | N697: 49.44294 | O697: 6.63562
D698: Mettlach | N698: 49.49426 | O698: 6.59766
D699: Namborn | N699: 49.52333 | O699: 7.14573
D700: Nennig | N700: 49.53812 | O700: 6.37608
D701: Neunkirchen (Saar) Hbf | N701: 49.2985 | O701: 7.05837
D702: Neunkirchen (Saar)-Wellesweiler | N702: 49.35464 | O702: 7.23634
D703: Niedaltdorf | N703: 49.34426 | O703: 6.59335
D704: Niederlinxweiler | N704: 49.43261 | O704: 7.15991
D705: Nittel | N705: 49.65409 | O705: 6.44176
... D3457: Hainewalde | N3457: 50.90698 | O3457: 14.70483
D3458: Hirschfelde | N3458: 14.89099 | O3458: ja
D3459: Horka Pbf | N3459: 51.30406 | O3459: 14.9024
D3460: Hoyerswerda | N3460: 51.43298 | O3460: 14.23188
D3461: Kamenz (Sachs) | N3461: 51.27362 | O3461: 14.09234
D3462: Kleinröhrsdorf | N3462: 51.13612 | O3462: 13.99142
D3463: Kodersdorf | N3463: 51.25897 | O3463: 14.91678
D3464: Kubschütz | N3464: 51.16489 | O3464: 14.50841
D3465: Lauta (Niederlausitz) | N3465: 51.44663 | O3465: 14.09271
D3466: Löbau (Sachs) | N3466: 51.09933 | O3466: 14.67147
D3467: Mittelherwigsdorf (Sachs) | N3467: 50.92321 | O3467: 14.74166
D3468: Neugersdorf | N3468: 50.98619 | O3468: 14.61052
D3469: Neukirch (Lausitz) Ost | N3469: 51.0909 | O3469: 14.32145
...

Sheet Elberadweg
A1: Lat | B1: Lon | C1: ID | D1: Bhf-Num | E1: Bhf-Nam | F1: Bhf-Lat | G1: Bhf-Lon | H1: Dist (KM)
A2: 50.887829 | B2: 14.234196 | E2: {=LOOKUP(1,1/FREQUENCY(0,SIN((RADIANS(Bhf!N$2:N$5383-A2))/2)^2+SIN((RADIANS(Bhf!O$2:O$5383-B2))/2)^2*COS(RADIANS(Bhf!N$2:N$5383))*COS(RADIANS(A2))),Bhf!D$2:D$5383)} -> Rathmannsdorf (Kr Pirna) | F2: {=LOOKUP(1,1/FREQUENCY(0,SIN((RADIANS(Bhf!N$2:N$5383-A2))/2)^2+SIN((RADIANS(Bhf!O$2:O$5383-B2))/2)^2*COS(RADIANS(Bhf!N$2:N$5383))*COS(RADIANS(A2))),Bhf!N$2:N$5383)} -> 50.93001 | G2: {=LOOKUP(1,1/FREQUENCY(0,SIN((RADIANS(Bhf!N$2:N$5383-A2))/2)^2+SIN((RADIANS(Bhf!O$2:O$5383-B2))/2)^2*COS(RADIANS(Bhf!N$2:N$5383))*COS(RADIANS(A2))),Bhf!O$2:O$5383)} -> 14.13123 | H2: =ACOS(COS(RADIANS(90-A2))*COS(RADIANS(90-F2))+SIN(RADIANS(90-A2))*SIN(RADIANS(90-F2))*COS(RADIANS(B2-G2)))*6371 -> 8.6092343
A3: 50.890051 | B3: 14.232318 | E3: {=LOOKUP(1,1/FREQUENCY(0,SIN((RADIANS(Bhf!N$2:N$5383-A3))/2)^2+SIN((RADIANS(Bhf!O$2:O$5383-B3))/2)^2*COS(RADIANS(Bhf!N$2:N$5383))*COS(RADIANS(A3))),Bhf!D$2:D$5383)} -> Rathmannsdorf (Kr Pirna) | F3: {=LOOKUP(1,1/FREQUENCY(0,SIN((RADIANS(Bhf!N$2:N$5383-A3))/2)^2+SIN((RADIANS(Bhf!O$2:O$5383-B3))/2)^2*COS(RADIANS(Bhf!N$2:N$5383))*COS(RADIANS(A3))),Bhf!N$2:N$5383)} -> 50.93001 | G3: {=LOOKUP(1,1/FREQUENCY(0,SIN((RADIANS(Bhf!N$2:N$5383-A3))/2)^2+SIN((RADIANS(Bhf!O$2:O$5383-B3))/2)^2*COS(RADIANS(Bhf!N$2:N$5383))*COS(RADIANS(A3))),Bhf!O$2:O$5383)} -> 14.13123 | H3: =ACOS(COS(RADIANS(90-A3))*COS(RADIANS(90-F3))+SIN(RADIANS(90-A3))*SIN(RADIANS(90-F3))*COS(RADIANS(B3-G3)))*6371 -> 8.365163
A4: 50.891537 | B4: 14.230946 | E4: {=LOOKUP(1,1/FREQUENCY(0,SIN((RADIANS(Bhf!N$2:N$5383-A4))/2)^2+SIN((RADIANS(Bhf!O$2:O$5383-B4))/2)^2*COS(RADIANS(Bhf!N$2:N$5383))*COS(RADIANS(A4))),Bhf!D$2:D$5383)} -> Rathmannsdorf (Kr Pirna) | F4: {=LOOKUP(1,1/FREQUENCY(0,SIN((RADIANS(Bhf!N$2:N$5383-A4))/2)^2+SIN((RADIANS(Bhf!O$2:O$5383-B4))/2)^2*COS(RADIANS(Bhf!N$2:N$5383))*COS(RADIANS(A4))),Bhf!N$2:N$5383)} -> 50.93001 | G4: {=LOOKUP(1,1/FREQUENCY(0,SIN((RADIANS(Bhf!N$2:N$5383-A4))/2)^2+SIN((RADIANS(Bhf!O$2:O$5383-B4))/2)^2*COS(RADIANS(Bhf!N$2:N$5383))*COS(RADIANS(A4))),Bhf!O$2:O$5383)} -> 14.13123 | H4: =ACOS(COS(RADIANS(90-A4))*COS(RADIANS(90-F4))+SIN(RADIANS(90-A4))*SIN(RADIANS(90-F4))*COS(RADIANS(B4-G4)))*6371 -> 8.1962803
A5: 50.891617 | B5: 14.230827 | E5: {=LOOKUP(1,1/FREQUENCY(0,SIN((RADIANS(Bhf!N$2:N$5383-A5))/2)^2+SIN((RADIANS(Bhf!O$2:O$5383-B5))/2)^2*COS(RADIANS(Bhf!N$2:N$5383))*COS(RADIANS(A5))),Bhf!D$2:D$5383)} -> Rathmannsdorf (Kr Pirna) | F5: {=LOOKUP(1,1/FREQUENCY(0,SIN((RADIANS(Bhf!N$2:N$5383-A5))/2)^2+SIN((RADIANS(Bhf!O$2:O$5383-B5))/2)^2*COS(RADIANS(Bhf!N$2:N$5383))*COS(RADIANS(A5))),Bhf!N$2:N$5383)} -> 50.93001 | G5: {=LOOKUP(1,1/FREQUENCY(0,SIN((RADIANS(Bhf!N$2:N$5383-A5))/2)^2+SIN((RADIANS(Bhf!O$2:O$5383-B5))/2)^2*COS(RADIANS(Bhf!N$2:N$5383))*COS(RADIANS(A5))),Bhf!O$2:O$5383)} -> 14.13123 | H5: =ACOS(COS(RADIANS(90-A5))*COS(RADIANS(90-F5))+SIN(RADIANS(90-A5))*SIN(RADIANS(90-F5))*COS(RADIANS(B5-G5)))*6371 -> 8.1845162
A6: 50.891569 | B6: 14.230726 | E6: {=LOOKUP(1,1/FREQUENCY(0,SIN((RADIANS(Bhf!N$2:N$5383-A6))/2)^2+SIN((RADIANS(Bhf!O$2:O$5383-B6))/2)^2*COS(RADIANS(Bhf!N$2:N$5383))*COS(RADIANS(A6))),Bhf!D$2:D$5383)} -> Rathmannsdorf (Kr Pirna) | F6: {=LOOKUP(1,1/FREQUENCY(0,SIN((RADIANS(Bhf!N$2:N$5383-A6))/2)^2+SIN((RADIANS(Bhf!O$2:O$5383-B6))/2)^2*COS(RADIANS(Bhf!N$2:N$5383))*COS(RADIANS(A6))),Bhf!N$2:N$5383)} -> 50.93001 | G6: {=LOOKUP(1,1/FREQUENCY(0,SIN((RADIANS(Bhf!N$2:N$5383-A6))/2)^2+SIN((RADIANS(Bhf!O$2:O$5383-B6))/2)^2*COS(RADIANS(Bhf!N$2:N$5383))*COS(RADIANS(A6))),Bhf!O$2:O$5383)} -> 14.13123 | H6: =ACOS(COS(RADIANS(90-A6))*COS(RADIANS(90-F6))+SIN(RADIANS(90-A6))*SIN(RADIANS(90-F6))*COS(RADIANS(B6-G6)))*6371 -> 8.1812658
A7: 50.89156 | B7: 14.230635 | E7: {=LOOKUP(1,1/FREQUENCY(0,SIN((RADIANS(Bhf!N$2:N$5383-A7))/2)^2+SIN((RADIANS(Bhf!O$2:O$5383-B7))/2)^2*COS(RADIANS(Bhf!N$2:N$5383))*COS(RADIANS(A7))),Bhf!D$2:D$5383)} -> Rathmannsdorf (Kr Pirna) | F7: {=LOOKUP(1,1/FREQUENCY(0,SIN((RADIANS(Bhf!N$2:N$5383-A7))/2)^2+SIN((RADIANS(Bhf!O$2:O$5383-B7))/2)^2*COS(RADIANS(Bhf!N$2:N$5383))*COS(RADIANS(A7))),Bhf!N$2:N$5383)} -> 50.93001 | G7: {=LOOKUP(1,1/FREQUENCY(0,SIN((RADIANS(Bhf!N$2:N$5383-A7))/2)^2+SIN((RADIANS(Bhf!O$2:O$5383-B7))/2)^2*COS(RADIANS(Bhf!N$2:N$5383))*COS(RADIANS(A7))),Bhf!O$2:O$5383)} -> 14.13123 | H7: =ACOS(COS(RADIANS(90-A7))*COS(RADIANS(90-F7))+SIN(RADIANS(90-A7))*SIN(RADIANS(90-F7))*COS(RADIANS(B7-G7)))*6371 -> 8.1763502
A8: 50.891567 | B8: 14.230516 | E8: {=LOOKUP(1,1/FREQUENCY(0,SIN((RADIANS(Bhf!N$2:N$5383-A8))/2)^2+SIN((RADIANS(Bhf!O$2:O$5383-B8))/2)^2*COS(RADIANS(Bhf!N$2:N$5383))*COS(RADIANS(A8))),Bhf!D$2:D$5383)} -> Rathmannsdorf (Kr Pirna) | F8: {=LOOKUP(1,1/FREQUENCY(0,SIN((RADIANS(Bhf!N$2:N$5383-A8))/2)^2+SIN((RADIANS(Bhf!O$2:O$5383-B8))/2)^2*COS(RADIANS(Bhf!N$2:N$5383))*COS(RADIANS(A8))),Bhf!N$2:N$5383)} -> 50.93001 | G8: {=LOOKUP(1,1/FREQUENCY(0,SIN((RADIANS(Bhf!N$2:N$5383-A8))/2)^2+SIN((RADIANS(Bhf!O$2:O$5383-B8))/2)^2*COS(RADIANS(Bhf!N$2:N$5383))*COS(RADIANS(A8))),Bhf!O$2:O$5383)} -> 14.13123 | H8: =ACOS(COS(RADIANS(90-A8))*COS(RADIANS(90-F8))+SIN(RADIANS(90-A8))*SIN(RADIANS(90-F8))*COS(RADIANS(B8-G8)))*6371 -> 8.1688318
A9: 50.891635 | B9: 14.23028 | E9: {=LOOKUP(1,1/FREQUENCY(0,SIN((RADIANS(Bhf!N$2:N$5383-A9))/2)^2+SIN((RADIANS(Bhf!O$2:O$5383-B9))/2)^2*COS(RADIANS(Bhf!N$2:N$5383))*COS(RADIANS(A9))),Bhf!D$2:D$5383)} -> Rathmannsdorf (Kr Pirna) | F9: {=LOOKUP(1,1/FREQUENCY(0,SIN((RADIANS(Bhf!N$2:N$5383-A9))/2)^2+SIN((RADIANS(Bhf!O$2:O$5383-B9))/2)^2*COS(RADIANS(Bhf!N$2:N$5383))*COS(RADIANS(A9))),Bhf!N$2:N$5383)} -> 50.93001 | G9: {=LOOKUP(1,1/FREQUENCY(0,SIN((RADIANS(Bhf!N$2:N$5383-A9))/2)^2+SIN((RADIANS(Bhf!O$2:O$5383-B9))/2)^2*COS(RADIANS(Bhf!N$2:N$5383))*COS(RADIANS(A9))),Bhf!O$2:O$5383)} -> 14.13123 | H9: =ACOS(COS(RADIANS(90-A9))*COS(RADIANS(90-F9))+SIN(RADIANS(90-A9))*SIN(RADIANS(90-F9))*COS(RADIANS(B9-G9)))*6371 -> 8.150771
A10: 50.891884 | B10: 14.229851 | E10: {=LOOKUP(1,1/FREQUENCY(0,SIN((RADIANS(Bhf!N$2:N$5383-A10))/2)^2+SIN((RADIANS(Bhf!O$2:O$5383-B10))/2)^2*COS(RADIANS(Bhf!N$2:N$5383))*COS(RADIANS(A10))),Bhf!D$2:D$5383)} -> Rathmannsdorf (Kr Pirna) | F10: {=LOOKUP(1,1/FREQUENCY(0,SIN((RADIANS(Bhf!N$2:N$5383-A10))/2)^2+SIN((RADIANS(Bhf!O$2:O$5383-B10))/2)^2*COS(RADIANS(Bhf!N$2:N$5383))*COS(RADIANS(A10))),Bhf!N$2:N$5383)} -> 50.93001 | G10: {=LOOKUP(1,1/FREQUENCY(0,SIN((RADIANS(Bhf!N$2:N$5383-A10))/2)^2+SIN((RADIANS(Bhf!O$2:O$5383-B10))/2)^2*COS(RADIANS(Bhf!N$2:N$5383))*COS(RADIANS(A10))),Bhf!O$2:O$5383)} -> 14.13123 | H10: =ACOS(COS(RADIANS(90-A10))*COS(RADIANS(90-F10))+SIN(RADIANS(90-A10))*SIN(RADIANS(90-F10))*COS(RADIANS(B10-G10)))*6371 -> 8.1106373
A11: 50.892492 | B11: 14.229177 | E11: {=LOOKUP(1,1/FREQUENCY(0,SIN((RADIANS(Bhf!N$2:N$5383-A11))/2)^2+SIN((RADIANS(Bhf!O$2:O$5383-B11))/2)^2*COS(RADIANS(Bhf!N$2:N$5383))*COS(RADIANS(A11))),Bhf!D$2:D$5383)} -> Rathmannsdorf (Kr Pirna) | F11: {=LOOKUP(1,1/FREQUENCY(0,SIN((RADIANS(Bhf!N$2:N$5383-A11))/2)^2+SIN((RADIANS(Bhf!O$2:O$5383-B11))/2)^2*COS(RADIANS(Bhf!N$2:N$5383))*COS(RADIANS(A11))),Bhf!N$2:N$5383)} -> 50.93001 | G11: {=LOOKUP(1,1/FREQUENCY(0,SIN((RADIANS(Bhf!N$2:N$5383-A11))/2)^2+SIN((RADIANS(Bhf!O$2:O$5383-B11))/2)^2*COS(RADIANS(Bhf!N$2:N$5383))*COS(RADIANS(A11))),Bhf!O$2:O$5383)} -> 14.13123 | H11: =ACOS(COS(RADIANS(90-A11))*COS(RADIANS(90-F11))+SIN(RADIANS(90-A11))*SIN(RADIANS(90-F11))*COS(RADIANS(B11-G11)))*6371 -> 8.0350428
A12: 50.893437 | B12: 14.228255 | E12: {=LOOKUP(1,1/FREQUENCY(0,SIN((RADIANS(Bhf!N$2:N$5383-A12))/2)^2+SIN((RADIANS(Bhf!O$2:O$5383-B12))/2)^2*COS(RADIANS(Bhf!N$2:N$5383))*COS(RADIANS(A12))),Bhf!D$2:D$5383)} -> Rathmannsdorf (Kr Pirna) | F12: {=LOOKUP(1,1/FREQUENCY(0,SIN((RADIANS(Bhf!N$2:N$5383-A12))/2)^2+SIN((RADIANS(Bhf!O$2:O$5383-B12))/2)^2*COS(RADIANS(Bhf!N$2:N$5383))*COS(RADIANS(A12))),Bhf!N$2:N$5383)} -> 50.93001 | G12: {=LOOKUP(1,1/FREQUENCY(0,SIN((RADIANS(Bhf!N$2:N$5383-A12))/2)^2+SIN((RADIANS(Bhf!O$2:O$5383-B12))/2)^2*COS(RADIANS(Bhf!N$2:N$5383))*COS(RADIANS(A12))),Bhf!O$2:O$5383)} -> 14.13123 | H12: =ACOS(COS(RADIANS(90-A12))*COS(RADIANS(90-F12))+SIN(RADIANS(90-A12))*SIN(RADIANS(90-F12))*COS(RADIANS(B12-G12)))*6371 -> 7.9253792
A13: 50.894984 | B13: 14.226882 | E13: {=LOOKUP(1,1/FREQUENCY(0,SIN((RADIANS(Bhf!N$2:N$5383-A13))/2)^2+SIN((RADIANS(Bhf!O$2:O$5383-B13))/2)^2*COS(RADIANS(Bhf!N$2:N$5383))*COS(RADIANS(A13))),Bhf!D$2:D$5383)} -> Rathmannsdorf (Kr Pirna) | F13: {=LOOKUP(1,1/FREQUENCY(0,SIN((RADIANS(Bhf!N$2:N$5383-A13))/2)^2+SIN((RADIANS(Bhf!O$2:O$5383-B13))/2)^2*COS(RADIANS(Bhf!N$2:N$5383))*COS(RADIANS(A13))),Bhf!N$2:N$5383)} -> 50.93001 | G13: {=LOOKUP(1,1/FREQUENCY(0,SIN((RADIANS(Bhf!N$2:N$5383-A13))/2)^2+SIN((RADIANS(Bhf!O$2:O$5383-B13))/2)^2*COS(RADIANS(Bhf!N$2:N$5383))*COS(RADIANS(A13))),Bhf!O$2:O$5383)} -> 14.13123 | H13: =ACOS(COS(RADIANS(90-A13))*COS(RADIANS(90-F13))+SIN(RADIANS(90-A13))*SIN(RADIANS(90-F13))*COS(RADIANS(B13-G13)))*6371 -> 7.7550154
... A4703: 53.891784 | B4703: 8.6815985 | E4703: {=LOOKUP(1,1/FREQUENCY(0,SIN((RADIANS(Bhf!N$2:N$5383-A4703))/2)^2+SIN((RADIANS(Bhf!O$2:O$5383-B4703))/2)^2*COS(RADIANS(Bhf!N$2:N$5383))*COS(RADIANS(A4703))),Bhf!D$2:D$5383)} -> Cadenberge | F4703: {=LOOKUP(1,1/FREQUENCY(0,SIN((RADIANS(Bhf!N$2:N$5383-A4703))/2)^2+SIN((RADIANS(Bhf!O$2:O$5383-B4703))/2)^2*COS(RADIANS(Bhf!N$2:N$5383))*COS(RADIANS(A4703))),Bhf!N$2:N$5383)} -> 53.76819 | G4703: {=LOOKUP(1,1/FREQUENCY(0,SIN((RADIANS(Bhf!N$2:N$5383-A4703))/2)^2+SIN((RADIANS(Bhf!O$2:O$5383-B4703))/2)^2*COS(RADIANS(Bhf!N$2:N$5383))*COS(RADIANS(A4703))),Bhf!O$2:O$5383)} -> 9.05821 | H4703: =ACOS(COS(RADIANS(90-A4703))*COS(RADIANS(90-F4703))+SIN(RADIANS(90-A4703))*SIN(RADIANS(90-F4703))*COS(RADIANS(B4703-G4703)))*6371 -> 28.279192
